test_reg_ok (test.case.user.test_xzs_reg.MyTestCase) ... ERROR
test_login_err01 (test.case.user.test_xzs_login.MyTestCase) ... ok
test_login_err02 (test.case.user.test_xzs_login.MyTestCase) ... ok
test_login_ok (test.case.user.test_xzs_login.MyTestCase) ... ok

======================================================================
ERROR: test_reg_ok (test.case.user.test_xzs_reg.MyTestCase)
----------------------------------------------------------------------
Traceback (most recent call last):
  File "D:\2226\接口自动化测试\224660723罗荃午5.10\test\case\user\test_xzs_reg.py", line 12, in test_reg_ok
    if check_user(noname):
  File "D:\2226\接口自动化测试\224660723罗荃午5.10\lib\db1.py", line 45, in check_user
    rel = query_db("select * from t_user where user_name ='{}'".format(name))
  File "D:\2226\接口自动化测试\224660723罗荃午5.10\lib\db1.py", line 13, in query_db
    con = conn()
  File "D:\2226\接口自动化测试\224660723罗荃午5.10\lib\db1.py", line 7, in conn
    con = pymysql.connect(host=db_host,port=db_port,user=db_user
  File "C:\Users\Administrator\AppData\Roaming\Python\Python38\site-packages\pymysql\connections.py", line 358, in __init__
    self.connect()
  File "C:\Users\Administrator\AppData\Roaming\Python\Python38\site-packages\pymysql\connections.py", line 664, in connect
    self._request_authentication()
  File "C:\Users\Administrator\AppData\Roaming\Python\Python38\site-packages\pymysql\connections.py", line 954, in _request_authentication
    auth_packet = self._read_packet()
  File "C:\Users\Administrator\AppData\Roaming\Python\Python38\site-packages\pymysql\connections.py", line 772, in _read_packet
    packet.raise_for_error()
  File "C:\Users\Administrator\AppData\Roaming\Python\Python38\site-packages\pymysql\protocol.py", line 221, in raise_for_error
    err.raise_mysql_exception(self._data)
  File "C:\Users\Administrator\AppData\Roaming\Python\Python38\site-packages\pymysql\err.py", line 143, in raise_mysql_exception
    raise errorclass(errno, errval)
pymysql.err.OperationalError: (1045, "Access denied for user 'root'@'localhost' (using password: YES)")

----------------------------------------------------------------------
Ran 4 tests in 0.059s

FAILED (errors=1)
